Workbook

Sheet Ambulift Travel Times
A1: StandCode | B1: CTA Doors | C1: Dom Arr Doors | D1: IA1 Doors | E1: IA2 Doors
A2: N/A | B2: 20.15 | D2: 8.87 | E2: 17.54
A3: 1 | B3: 16.06 | D3: 21.55 | E3: 34.62
A4: 10 | C4: 13.73 | D4: 9.87 | E4: 19.98
A5: 100 | B5: 32.43 | D5: 30.85 | E5: 20.8
A6: 102 | D6: 20.8 | E6: 11.95
A7: 103 | C7: 9.9 | D7: 19.93 | E7: 24.95
A8: 104 | D8: 40.07 | E8: 27.06
A9: 105 | D9: 12.95 | E9: 12.22
A10: 106 | C10: 42.02 | D10: 11.36 | E10: 13.21
A11: 11 | D11: 29.53 | E11: 17.6
A12: 12 | E12: 38.14
A13: 14 | E13: 21.63
A14: 15 | E14: 31.7
A15: 15A | C15: 5.54 | D15: 12.39 | E15: 20.71
A16: 15B | B16: 26.48 | C16: 16.43 | D16: 23.02 | E16: 24.01
A17: 16 | E17: 12.91
A18: 16A | C18: 24.22 | D18: 13.22 | E18: 19.48
A19: 16B | E19: 17.3
A20: 17 | C20: 20.67 | D20: 39.45 | E20: 20.38
A21: 18 | E21: 20.52
A22: 1A | B22: 16.78 | C22: 16 | D22: 20.26 | E22: 22.79
A23: 1B | B23: 16.15 | C23: 28.78 | D23: 23.01 | E23: 30.44
A24: 2 | B24: 9.52 | C24: 12 | D24: 15.48 | E24: 14
A25: 20 | B25: 15.86 | C25: 11.75 | E25: 23.14
A26: 22 | C26: 16.88 | E26: 16.82
A27: 24 | B27: 5.36 | C27: 12.95 | E27: 20.86
A28: 25 | B28: 31.39 | E28: 16.38
A29: 27 | E29: 13.82
A30: 28 | B30: 11.48 | E30: 26.71
A31: 29 | B31: 18.72 | E31: 8.49
A32: 3 | B32: 1.67 | C32: 33.67 | D32: 16.6 | E32: 10.36
A33: 30 | E33: 26.87
A34: 308 | B34: 26.37 | D34: 16.68 | E34: 21.63
A35: 309 | B35: 17.67 | D35: 9.12 | E35: 30.93
A36: 31 | C36: 22.42 | E36: 16.51
A37: 310 | C37: 24.67 | E37: 19.95
A38: 311 | B38: 49.17 | E38: 17.99
A39: 312 | B39: 39.17 | D39: 10.89 | E39: 15.35
A40: 313 | D40: 67.45 | E40: 36.06
...

Sheet Minibus Travel Times
A1: StandCode | B1: CTA Doors | C1: Dom Arr Doors | D1: IA1 Doors | E1: IA2 Doors
A2: N/A | D2: 4.63 | E2: 12.23
A3: 1 | C3: 21.57
A4: 10 | E4: 12.83
A5: 100 | E5: 17.43
A6: 102 | C6: 10.88 | E6: 10.73
A7: 103 | E7: 12.8
A8: 104 | E8: 7.48
A9: 106 | E9: 24.72
A10: 11 | E10: 3.83
A11: 14 | E11: 16.15
A12: 15A | D12: 12.92 | E12: 8.77
A13: 15B | E13: 9.36
A14: 16A | E14: 17.64
A15: 16B | E15: 10.41
A16: 17 | C16: 3.75 | E16: 8.31
A17: 19 | D17: 19.43
A18: 1A | B18: 7.5 | D18: 4.69
A19: 1B | B19: 9.82
A20: 2 | E20: 9.9
A21: 20 | C21: 7.03 | E21: 20.2
A22: 22 | B22: 8.1 | E22: 11.42
A23: 24 | B23: 13.56 | C23: 3.28 | E23: 19.45
A24: 25 | E24: 7.51
A25: 27 | B25: 15.98
A26: 29 | E26: 29.9
A27: 3 | D27: 7.47 | E27: 15.84
A28: 30 | E28: 10.44
A29: 308 | B29: 13.95 | E29: 18.42
A30: 309 | E30: 21.48
A31: 31 | E31: 10.99
A32: 310 | E32: 30.08
A33: 311 | E33: 15.41
A34: 312 | D34: 1.63 | E34: 12.48
A35: 32 | C35: 11.19
A36: 33 | E36: 12.72
A37: 4 | C37: 9.2 | D37: 5.73
A38: 5 | B38: 9.12
A39: 6 | D39: 6.93 | E39: 11.13
A40: 7 | B40: 8.73 | D40: 12.84
...

Sheet Sheet1
A1: StandCode | B1: CTA Doors | C1: Dom Arr Doors | D1: IA1 Doors | E1: IA2 Doors
B2: ='Ambulift Travel Times'!B2-'Minibus Travel Times'!B2 -> 20.15 | C2: ='Ambulift Travel Times'!C2-'Minibus Travel Times'!C2 -> 0 | D2: ='Ambulift Travel Times'!D2-'Minibus Travel Times'!D2 -> 4.24 | E2: ='Ambulift Travel Times'!E2-'Minibus Travel Times'!E2 -> 5.31
A3: 1 | B3: ='Ambulift Travel Times'!B3-'Minibus Travel Times'!B3 -> 16.06 | C3: ='Ambulift Travel Times'!C3-'Minibus Travel Times'!C3 -> -21.57 | D3: ='Ambulift Travel Times'!D3-'Minibus Travel Times'!D3 -> 21.55 | E3: ='Ambulift Travel Times'!E3-'Minibus Travel Times'!E3 -> 34.62
A4: 10 | B4: ='Ambulift Travel Times'!B4-'Minibus Travel Times'!B4 -> 0 | C4: ='Ambulift Travel Times'!C4-'Minibus Travel Times'!C4 -> 13.73 | D4: ='Ambulift Travel Times'!D4-'Minibus Travel Times'!D4 -> 9.87 | E4: ='Ambulift Travel Times'!E4-'Minibus Travel Times'!E4 -> 7.15
A5: 100 | B5: ='Ambulift Travel Times'!B5-'Minibus Travel Times'!B5 -> 32.43 | C5: ='Ambulift Travel Times'!C5-'Minibus Travel Times'!C5 -> 0 | D5: ='Ambulift Travel Times'!D5-'Minibus Travel Times'!D5 -> 30.85 | E5: ='Ambulift Travel Times'!E5-'Minibus Travel Times'!E5 -> 3.37 | G5: Both
A6: 102 | B6: ='Ambulift Travel Times'!B6-'Minibus Travel Times'!B6 -> 0 | C6: ='Ambulift Travel Times'!C6-'Minibus Travel Times'!C6 -> -10.88 | D6: ='Ambulift Travel Times'!D6-'Minibus Travel Times'!D6 -> 20.8 | E6: ='Ambulift Travel Times'!E6-'Minibus Travel Times'!E6 -> 1.22 | G6: Ambulift only
A7: 103 | B7: ='Ambulift Travel Times'!B7-'Minibus Travel Times'!B7 -> 0 | C7: ='Ambulift Travel Times'!C7-'Minibus Travel Times'!C7 -> 9.9 | D7: ='Ambulift Travel Times'!D7-'Minibus Travel Times'!D7 -> 19.93 | E7: ='Ambulift Travel Times'!E7-'Minibus Travel Times'!E7 -> 12.15 | G7: Minibus only
A8: 104 | B8: ='Ambulift Travel Times'!B8-'Minibus Travel Times'!B8 -> 0 | C8: ='Ambulift Travel Times'!C8-'Minibus Travel Times'!C8 -> 0 | D8: ='Ambulift Travel Times'!D8-'Minibus Travel Times'!D8 -> 40.07 | E8: ='Ambulift Travel Times'!E8-'Minibus Travel Times'!E8 -> 19.58
A9: 105 | B9: ='Ambulift Travel Times'!B9-'Minibus Travel Times'!B9 -> 0 | C9: ='Ambulift Travel Times'!C9-'Minibus Travel Times'!C9 -> 0 | D9: ='Ambulift Travel Times'!D9-'Minibus Travel Times'!D9 -> 12.95 | E9: ='Ambulift Travel Times'!E9-'Minibus Travel Times'!E9 -> -12.5
A10: 106 | B10: ='Ambulift Travel Times'!B10-'Minibus Travel Times'!B10 -> 0 | C10: ='Ambulift Travel Times'!C10-'Minibus Travel Times'!C10 -> 42.02 | D10: ='Ambulift Travel Times'!D10-'Minibus Travel Times'!D10 -> 11.36 | E10: ='Ambulift Travel Times'!E10-'Minibus Travel Times'!E10 -> 9.38
A11: 11 | B11: ='Ambulift Travel Times'!B11-'Minibus Travel Times'!B11 -> 0 | C11: ='Ambulift Travel Times'!C11-'Minibus Travel Times'!C11 -> 0 | D11: ='Ambulift Travel Times'!D11-'Minibus Travel Times'!D11 -> 29.53 | E11: ='Ambulift Travel Times'!E11-'Minibus Travel Times'!E11 -> 1.45
A12: 12 | B12: ='Ambulift Travel Times'!B12-'Minibus Travel Times'!B12 -> 0 | C12: ='Ambulift Travel Times'!C12-'Minibus Travel Times'!C12 -> 0 | D12: ='Ambulift Travel Times'!D12-'Minibus Travel Times'!D12 -> -12.92 | E12: ='Ambulift Travel Times'!E12-'Minibus Travel Times'!E12 -> 29.37
A13: 14 | B13: ='Ambulift Travel Times'!B13-'Minibus Travel Times'!B13 -> 0 | C13: ='Ambulift Travel Times'!C13-'Minibus Travel Times'!C13 -> 0 | D13: ='Ambulift Travel Times'!D13-'Minibus Travel Times'!D13 -> 0 | E13: ='Ambulift Travel Times'!E13-'Minibus Travel Times'!E13 -> 12.27
A14: 15 | B14: ='Ambulift Travel Times'!B14-'Minibus Travel Times'!B14 -> 0 | C14: ='Ambulift Travel Times'!C14-'Minibus Travel Times'!C14 -> 0 | D14: ='Ambulift Travel Times'!D14-'Minibus Travel Times'!D14 -> 0 | E14: ='Ambulift Travel Times'!E14-'Minibus Travel Times'!E14 -> 14.06
A15: 15A | B15: ='Ambulift Travel Times'!B15-'Minibus Travel Times'!B15 -> 0 | C15: ='Ambulift Travel Times'!C15-'Minibus Travel Times'!C15 -> 5.54 | D15: ='Ambulift Travel Times'!D15-'Minibus Travel Times'!D15 -> 12.39 | E15: ='Ambulift Travel Times'!E15-'Minibus Travel Times'!E15 -> 10.3
A16: 15B | B16: ='Ambulift Travel Times'!B16-'Minibus Travel Times'!B16 -> 26.48 | C16: ='Ambulift Travel Times'!C16-'Minibus Travel Times'!C16 -> 12.68 | D16: ='Ambulift Travel Times'!D16-'Minibus Travel Times'!D16 -> 23.02 | E16: ='Ambulift Travel Times'!E16-'Minibus Travel Times'!E16 -> 15.7
A17: 16 | B17: ='Ambulift Travel Times'!B17-'Minibus Travel Times'!B17 -> 0 | C17: ='Ambulift Travel Times'!C17-'Minibus Travel Times'!C17 -> 0 | D17: ='Ambulift Travel Times'!D17-'Minibus Travel Times'!D17 -> -19.43 | E17: ='Ambulift Travel Times'!E17-'Minibus Travel Times'!E17 -> 12.91
A18: 16A | B18: ='Ambulift Travel Times'!B18-'Minibus Travel Times'!B18 -> -7.5 | C18: ='Ambulift Travel Times'!C18-'Minibus Travel Times'!C18 -> 24.22 | D18: ='Ambulift Travel Times'!D18-'Minibus Travel Times'!D18 -> 8.53 | E18: ='Ambulift Travel Times'!E18-'Minibus Travel Times'!E18 -> 19.48
A19: 16B | B19: ='Ambulift Travel Times'!B19-'Minibus Travel Times'!B19 -> -9.82 | C19: ='Ambulift Travel Times'!C19-'Minibus Travel Times'!C19 -> 0 | D19: ='Ambulift Travel Times'!D19-'Minibus Travel Times'!D19 -> 0 | E19: ='Ambulift Travel Times'!E19-'Minibus Travel Times'!E19 -> 17.3
... A52: 9 | B52: ='Ambulift Travel Times'!B52-'Minibus Travel Times'!B52 -> 0 | C52: ='Ambulift Travel Times'!C52-'Minibus Travel Times'!C52 -> 14.73 | D52: ='Ambulift Travel Times'!D52-'Minibus Travel Times'!D52 -> 29.72 | E52: ='Ambulift Travel Times'!E52-'Minibus Travel Times'!E52 -> 25.71
